Workbook

Sheet Assumptions
A1: Indonesian Learning Bot - Financial Model (High-Level Estimates)
A2: Telegram bot teaching Indonesian to English speakers. Blue = editable inputs. Black = formulas. Figures are planning estimates, not guarantees.
A4: INPUTS (edit the blue cells to test your own assumptions)
A5: Driver | B5: Conservative | C5: Base | D5: Optimistic | E5: Notes
A6: New free users acquired / month (steady state) | B6: 300 | C6: 800 | D6: 2000 | E6: People who start the bot each month
A7: Free -> Paid conversion | B7: 0.02 | C7: 0.04 | D7: 0.07 | E7: Balabol got ~1.5%; Bino ~15% (with methodologist)
A8: Monthly churn (paid) | B8: 0.12 | C8: 0.09 | D8: 0.06 | E8: Language apps churn high; annual plans lower it
A9: Blended ARPU ($ / paying user / month) | B9: 8 | C9: 8.5 | D9: 9 | E9: Monthly $9.99 / annual ~$59 blended
A10: Payment + platform fee | B10: 0.3 | C10: 0.3 | D10: 0.22 | E10: Telegram Stars via app stores ~30%; web checkout lower
A11: Variable cost ($ / active paid / month) | B11: 1.5 | C11: 1.5 | D11: 1.2 | E11: LLM dialogue + TTS/STT + infra per active user
A12: CAC ($ / paying customer) | B12: 15 | C12: 8 | D12: 4 | E12: Lower = organic/referral heavy. Balabol CAC ~$28 killed it
A13: Fixed cost ($ / month) | B13: 300 | C13: 300 | D13: 300 | E13: Hosting, tools, content upkeep; founder unpaid
A15: UNIT ECONOMICS (calculated)
A16: Metric | B16: Conservative | C16: Base | D16: Optimistic | E16: Definition
A17: Net revenue / paid / month | B17: =B9*(1-B10) -> 5.6 | C17: =C9*(1-C10) -> 5.95 | D17: =D9*(1-D10) -> 7.02 | E17: ARPU after platform fee
A18: Contribution / paid / month | B18: =B9*(1-B10)-B11 -> 4.1 | C18: =C9*(1-C10)-C11 -> 4.45 | D18: =D9*(1-D10)-D11 -> 5.82 | E18: Net revenue minus variable cost
A19: Avg customer lifetime (months) | B19: =1/B8 -> 8.3333333 | C19: =1/C8 -> 11.111111 | D19: =1/D8 -> 16.666667 | E19: 1 / monthly churn
A20: LTV ($) | B20: =(B9*(1-B10)-B11)/B8 -> 34.166667 | C20: =(C9*(1-C10)-C11)/C8 -> 49.444444 | D20: =(D9*(1-D10)-D11)/D8 -> 97 | E20: Contribution x lifetime
A21: LTV / CAC ratio | B21: =((B9*(1-B10)-B11)/B8)/B12 -> 2.2777778 | C21: =((C9*(1-C10)-C11)/C8)/C12 -> 6.1805556 | D21: =((D9*(1-D10)-D11)/D8)/D12 -> 24.25 | E21: >3x healthy; <1x loses money
A22: CAC payback (months) | B22: =B12/(B9*(1-B10)-B11) -> 3.6585366 | C22: =C12/(C9*(1-C10)-C11) -> 1.7977528 | D22: =D12/(D9*(1-D10)-D11) -> 0.68728522 | E22: Months to recover acquisition cost

Sheet 12-Month Projection
A1: 12-Month Projection - three scenarios
A2: Paid base = prior base x (1 - churn) + new paid. Net profit assumes founder takes no salary.
A4: CONSERVATIVE SCENARIO
A5: Metric / Month | B5: M1 | C5: M2 | D5: M3 | E5: M4 | F5: M5 | G5: M6 | H5: M7 | I5: M8 | J5: M9 | K5: M10 | L5: M11 | M5: M12 | N5: Year 1
A6: New free users | B6: =Assumptions!$B$6 -> 300 | C6: =Assumptions!$B$6 -> 300 | D6: =Assumptions!$B$6 -> 300 | E6: =Assumptions!$B$6 -> 300 | F6: =Assumptions!$B$6 -> 300 | G6: =Assumptions!$B$6 -> 300 | H6: =Assumptions!$B$6 -> 300 | I6: =Assumptions!$B$6 -> 300 | ... M6: =Assumptions!$B$6 -> 300 | N6: =SUM(B6:M6) -> 3600
A7: New paying customers | B7: =B6*Assumptions!$B$7 -> 6 | C7: =C6*Assumptions!$B$7 -> 6 | D7: =D6*Assumptions!$B$7 -> 6 | E7: =E6*Assumptions!$B$7 -> 6 | F7: =F6*Assumptions!$B$7 -> 6 | G7: =G6*Assumptions!$B$7 -> 6 | H7: =H6*Assumptions!$B$7 -> 6 | I7: =I6*Assumptions!$B$7 -> 6 | ... M7: =M6*Assumptions!$B$7 -> 6 | N7: =SUM(B7:M7) -> 72
A8: Churned paying customers | B8: 0 | C8: =B9*Assumptions!$B$8 -> 0.72 | D8: =C9*Assumptions!$B$8 -> 1.3536 | E8: =D9*Assumptions!$B$8 -> 1.911168 | F8: =E9*Assumptions!$B$8 -> 2.4018278 | G8: =F9*Assumptions!$B$8 -> 2.8336085 | H8: =G9*Assumptions!$B$8 -> 3.2135755 | I8: =H9*Assumptions!$B$8 -> 3.5479464 | J8: =I9*Assumptions!$B$8 -> 3.8421929 | ... M8: =L9*Assumptions!$B$8 -> 4.5295148 | N8: =SUM(B8:M8) -> 32.783558
A9: Active paying base (end of month) | B9: =B7 -> 6 | C9: =B9*(1-Assumptions!$B$8)+C7 -> 11.28 | D9: =C9*(1-Assumptions!$B$8)+D7 -> 15.9264 | E9: =D9*(1-Assumptions!$B$8)+E7 -> 20.015232 | F9: =E9*(1-Assumptions!$B$8)+F7 -> 23.613404 | G9: =F9*(1-Assumptions!$B$8)+G7 -> 26.779796 | H9: =G9*(1-Assumptions!$B$8)+H7 -> 29.56622 | I9: =H9*(1-Assumptions!$B$8)+I7 -> 32.018274 | J9: =I9*(1-Assumptions!$B$8)+J7 -> 34.176081 | ... M9: =L9*(1-Assumptions!$B$8)+M7 -> 39.216442 | N9: =M9 -> 39.216442
A10: Gross MRR ($) | B10: =B9*Assumptions!$B$9 -> 48 | C10: =C9*Assumptions!$B$9 -> 90.24 | D10: =D9*Assumptions!$B$9 -> 127.4112 | E10: =E9*Assumptions!$B$9 -> 160.12186 | F10: =F9*Assumptions!$B$9 -> 188.90723 | G10: =G9*Assumptions!$B$9 -> 214.23837 | H10: =H9*Assumptions!$B$9 -> 236.52976 | I10: =I9*Assumptions!$B$9 -> 256.14619 | ... M10: =M9*Assumptions!$B$9 -> 313.73154 | N10: =M10 -> 313.73154
A11: Net revenue ($) | B11: =B9*Assumptions!$B$9*(1-Assumptions!$B$10) -> 33.6 | C11: =C9*Assumptions!$B$9*(1-Assumptions!$B$10) -> 63.168 | D11: =D9*Assumptions!$B$9*(1-Assumptions!$B$10) -> 89.18784 | E11: =E9*Assumptions!$B$9*(1-Assumptions!$B$10) -> 112.0853 | F11: =F9*Assumptions!$B$9*(1-Assumptions!$B$10) -> 132.23506 | G11: =G9*Assumptions!$B$9*(1-Assumptions!$B$10) -> 149.96686 | H11: =H9*Assumptions!$B$9*(1-Assumptions!$B$10) -> 165.57083 | I11: =I9*Assumptions!$B$9*(1-Assumptions!$B$10) -> 179.30233 | ... M11: =M9*Assumptions!$B$9*(1-Assumptions!$B$10) -> 219.61208 | N11: =SUM(B11:M11) -> 1749.5114
A12: Variable cost ($) | B12: =B9*Assumptions!$B$11 -> 9 | C12: =C9*Assumptions!$B$11 -> 16.92 | D12: =D9*Assumptions!$B$11 -> 23.8896 | E12: =E9*Assumptions!$B$11 -> 30.022848 | F12: =F9*Assumptions!$B$11 -> 35.420106 | G12: =G9*Assumptions!$B$11 -> 40.169693 | H12: =H9*Assumptions!$B$11 -> 44.34933 | I12: =I9*Assumptions!$B$11 -> 48.027411 | ... M12: =M9*Assumptions!$B$11 -> 58.824663 | N12: =SUM(B12:M12) -> 468.61914
A13: Marketing / CAC spend ($) | B13: =B7*Assumptions!$B$12 -> 90 | C13: =C7*Assumptions!$B$12 -> 90 | D13: =D7*Assumptions!$B$12 -> 90 | E13: =E7*Assumptions!$B$12 -> 90 | F13: =F7*Assumptions!$B$12 -> 90 | G13: =G7*Assumptions!$B$12 -> 90 | H13: =H7*Assumptions!$B$12 -> 90 | I13: =I7*Assumptions!$B$12 -> 90 | ... M13: =M7*Assumptions!$B$12 -> 90 | N13: =SUM(B13:M13) -> 1080
A14: Fixed cost ($) | B14: =Assumptions!$B$13 -> 300 | C14: =Assumptions!$B$13 -> 300 | D14: =Assumptions!$B$13 -> 300 | E14: =Assumptions!$B$13 -> 300 | F14: =Assumptions!$B$13 -> 300 | G14: =Assumptions!$B$13 -> 300 | H14: =Assumptions!$B$13 -> 300 | I14: =Assumptions!$B$13 -> 300 | ... M14: =Assumptions!$B$13 -> 300 | N14: =SUM(B14:M14) -> 3600
A15: Net profit / (loss) ($) | B15: =B11-B12-B13-B14 -> -365.4 | C15: =C11-C12-C13-C14 -> -343.752 | D15: =D11-D12-D13-D14 -> -324.70176 | E15: =E11-E12-E13-E14 -> -307.93755 | F15: =F11-F12-F13-F14 -> -293.18504 | G15: =G11-G12-G13-G14 -> -280.20284 | H15: =H11-H12-H13-H14 -> -268.7785 | I15: =I11-I12-I13-I14 -> -258.72508 | ... M15: =M11-M12-M13-M14 -> -229.21259 | N15: =SUM(B15:M15) -> -3399.1077
A16: Cumulative net profit ($) | B16: =B15 -> -365.4 | C16: =B16+C15 -> -709.152 | D16: =C16+D15 -> -1033.8538 | E16: =D16+E15 -> -1341.7913 | F16: =E16+F15 -> -1634.9764 | G16: =F16+G15 -> -1915.1792 | H16: =G16+H15 -> -2183.9577 | I16: =H16+I15 -> -2442.6828 | J16: =I16+J15 -> -2692.5608 | ... M16: =L16+M15 -> -3399.1077 | N16: =M16 -> -3399.1077
A19: BASE SCENARIO
A20: Metric / Month | B20: M1 | C20: M2 | D20: M3 | E20: M4 | F20: M5 | G20: M6 | H20: M7 | I20: M8 | J20: M9 | K20: M10 | L20: M11 | M20: M12 | N20: Year 1
A21: New free users | B21: =Assumptions!$C$6 -> 800 | C21: =Assumptions!$C$6 -> 800 | D21: =Assumptions!$C$6 -> 800 | E21: =Assumptions!$C$6 -> 800 | F21: =Assumptions!$C$6 -> 800 | G21: =Assumptions!$C$6 -> 800 | H21: =Assumptions!$C$6 -> 800 | I21: =Assumptions!$C$6 -> 800 | ... M21: =Assumptions!$C$6 -> 800 | N21: =SUM(B21:M21) -> 9600
A22: New paying customers | B22: =B21*Assumptions!$C$7 -> 32 | C22: =C21*Assumptions!$C$7 -> 32 | D22: =D21*Assumptions!$C$7 -> 32 | E22: =E21*Assumptions!$C$7 -> 32 | F22: =F21*Assumptions!$C$7 -> 32 | G22: =G21*Assumptions!$C$7 -> 32 | H22: =H21*Assumptions!$C$7 -> 32 | I22: =I21*Assumptions!$C$7 -> 32 | ... M22: =M21*Assumptions!$C$7 -> 32 | N22: =SUM(B22:M22) -> 384
A23: Churned paying customers | B23: 0 | C23: =B24*Assumptions!$C$8 -> 2.88 | D23: =C24*Assumptions!$C$8 -> 5.5008 | E23: =D24*Assumptions!$C$8 -> 7.885728 | F23: =E24*Assumptions!$C$8 -> 10.056012 | G23: =F24*Assumptions!$C$8 -> 12.030971 | H23: =G24*Assumptions!$C$8 -> 13.828184 | I23: =H24*Assumptions!$C$8 -> 15.463647 | J23: =I24*Assumptions!$C$8 -> 16.951919 | ... M23: =L24*Assumptions!$C$8 -> 20.660203 | N23: =SUM(B23:M23) -> 143.1024
A24: Active paying base (end of month) | B24: =B22 -> 32 | C24: =B24*(1-Assumptions!$C$8)+C22 -> 61.12 | D24: =C24*(1-Assumptions!$C$8)+D22 -> 87.6192 | E24: =D24*(1-Assumptions!$C$8)+E22 -> 111.73347 | F24: =E24*(1-Assumptions!$C$8)+F22 -> 133.67746 | G24: =F24*(1-Assumptions!$C$8)+G22 -> 153.64649 | H24: =G24*(1-Assumptions!$C$8)+H22 -> 171.8183 | I24: =H24*(1-Assumptions!$C$8)+I22 -> 188.35466 | J24: =I24*(1-Assumptions!$C$8)+J22 -> 203.40274 | ... M24: =L24*(1-Assumptions!$C$8)+M22 -> 240.8976 | N24: =M24 -> 240.8976
A25: Gross MRR ($) | B25: =B24*Assumptions!$C$9 -> 272 | C25: =C24*Assumptions!$C$9 -> 519.52 | D25: =D24*Assumptions!$C$9 -> 744.7632 | E25: =E24*Assumptions!$C$9 -> 949.73451 | F25: =F24*Assumptions!$C$9 -> 1136.2584 | G25: =G24*Assumptions!$C$9 -> 1305.9951 | H25: =H24*Assumptions!$C$9 -> 1460.4556 | I25: =I24*Assumptions!$C$9 -> 1601.0146 | ... M25: =M24*Assumptions!$C$9 -> 2047.6296 | N25: =M25 -> 2047.6296
A26: Net revenue ($) | B26: =B24*Assumptions!$C$9*(1-Assumptions!$C$10) -> 190.4 | C26: =C24*Assumptions!$C$9*(1-Assumptions!$C$10) -> 363.664 | D26: =D24*Assumptions!$C$9*(1-Assumptions!$C$10) -> 521.33424 | E26: =E24*Assumptions!$C$9*(1-Assumptions!$C$10) -> 664.81416 | F26: =F24*Assumptions!$C$9*(1-Assumptions!$C$10) -> 795.38088 | G26: =G24*Assumptions!$C$9*(1-Assumptions!$C$10) -> 914.1966 | H26: =H24*Assumptions!$C$9*(1-Assumptions!$C$10) -> 1022.3189 | I26: =I24*Assumptions!$C$9*(1-Assumptions!$C$10) -> 1120.7102 | ... M26: =M24*Assumptions!$C$9*(1-Assumptions!$C$10) -> 1433.3407 | N26: =SUM(B26:M26) -> 10893.999
A27: Variable cost ($) | B27: =B24*Assumptions!$C$11 -> 48 | C27: =C24*Assumptions!$C$11 -> 91.68 | D27: =D24*Assumptions!$C$11 -> 131.4288 | E27: =E24*Assumptions!$C$11 -> 167.60021 | F27: =F24*Assumptions!$C$11 -> 200.51619 | G27: =G24*Assumptions!$C$11 -> 230.46973 | H27: =H24*Assumptions!$C$11 -> 257.72746 | I27: =I24*Assumptions!$C$11 -> 282.53199 | ... M27: =M24*Assumptions!$C$11 -> 361.34641 | N27: =SUM(B27:M27) -> 2746.3863
A28: Marketing / CAC spend ($) | B28: =B22*Assumptions!$C$12 -> 256 | C28: =C22*Assumptions!$C$12 -> 256 | D28: =D22*Assumptions!$C$12 -> 256 | E28: =E22*Assumptions!$C$12 -> 256 | F28: =F22*Assumptions!$C$12 -> 256 | G28: =G22*Assumptions!$C$12 -> 256 | H28: =H22*Assumptions!$C$12 -> 256 | I28: =I22*Assumptions!$C$12 -> 256 | ... M28: =M22*Assumptions!$C$12 -> 256 | N28: =SUM(B28:M28) -> 3072
A29: Fixed cost ($) | B29: =Assumptions!$C$13 -> 300 | C29: =Assumptions!$C$13 -> 300 | D29: =Assumptions!$C$13 -> 300 | E29: =Assumptions!$C$13 -> 300 | F29: =Assumptions!$C$13 -> 300 | G29: =Assumptions!$C$13 -> 300 | H29: =Assumptions!$C$13 -> 300 | I29: =Assumptions!$C$13 -> 300 | ... M29: =Assumptions!$C$13 -> 300 | N29: =SUM(B29:M29) -> 3600
A30: Net profit / (loss) ($) | B30: =B26-B27-B28-B29 -> -413.6 | C30: =C26-C27-C28-C29 -> -284.016 | D30: =D26-D27-D28-D29 -> -166.09456 | E30: =E26-E27-E28-E29 -> -58.78605 | F30: =F26-F27-F28-F29 -> 38.864695 | G30: =G26-G27-G28-G29 -> 127.72687 | H30: =H26-H27-H28-H29 -> 208.59145 | I30: =I26-I27-I28-I29 -> 282.17822 | ... M30: =M26-M27-M28-M29 -> 515.99434 | N30: =SUM(B30:M30) -> 1475.6128
A31: Cumulative net profit ($) | B31: =B30 -> -413.6 | C31: =B31+C30 -> -697.616 | D31: =C31+D30 -> -863.71056 | E31: =D31+E30 -> -922.49661 | F31: =E31+F30 -> -883.63191 | G31: =F31+G30 -> -755.90504 | H31: =G31+H30 -> -547.31359 | I31: =H31+I30 -> -265.13537 | J31: =I31+J30 -> 84.006817 | ... M31: =L31+M30 -> 1475.6128 | N31: =M31 -> 1475.6128
A34: OPTIMISTIC SCENARIO
A35: Metric / Month | B35: M1 | C35: M2 | D35: M3 | E35: M4 | F35: M5 | G35: M6 | H35: M7 | I35: M8 | J35: M9 | K35: M10 | L35: M11 | M35: M12 | N35: Year 1
A36: New free users | B36: =Assumptions!$D$6 -> 2000 | C36: =Assumptions!$D$6 -> 2000 | D36: =Assumptions!$D$6 -> 2000 | E36: =Assumptions!$D$6 -> 2000 | F36: =Assumptions!$D$6 -> 2000 | G36: =Assumptions!$D$6 -> 2000 | H36: =Assumptions!$D$6 -> 2000 | I36: =Assumptions!$D$6 -> 2000 | ... M36: =Assumptions!$D$6 -> 2000 | N36: =SUM(B36:M36) -> 24000
A37: New paying customers | B37: =B36*Assumptions!$D$7 -> 140 | C37: =C36*Assumptions!$D$7 -> 140 | D37: =D36*Assumptions!$D$7 -> 140 | E37: =E36*Assumptions!$D$7 -> 140 | F37: =F36*Assumptions!$D$7 -> 140 | G37: =G36*Assumptions!$D$7 -> 140 | H37: =H36*Assumptions!$D$7 -> 140 | I37: =I36*Assumptions!$D$7 -> 140 | ... M37: =M36*Assumptions!$D$7 -> 140 | N37: =SUM(B37:M37) -> 1680
A38: Churned paying customers | B38: 0 | C38: =B39*Assumptions!$D$8 -> 8.4 | D38: =C39*Assumptions!$D$8 -> 16.296 | E38: =D39*Assumptions!$D$8 -> 23.71824 | F38: =E39*Assumptions!$D$8 -> 30.695146 | G38: =F39*Assumptions!$D$8 -> 37.253437 | H38: =G39*Assumptions!$D$8 -> 43.418231 | I38: =H39*Assumptions!$D$8 -> 49.213137 | J38: =I39*Assumptions!$D$8 -> 54.660349 | ... M38: =L39*Assumptions!$D$8 -> 69.118251 | N38: =SUM(B38:M38) -> 457.1474
A39: Active paying base (end of month) | B39: =B37 -> 140 | C39: =B39*(1-Assumptions!$D$8)+C37 -> 271.6 | D39: =C39*(1-Assumptions!$D$8)+D37 -> 395.304 | E39: =D39*(1-Assumptions!$D$8)+E37 -> 511.58576 | F39: =E39*(1-Assumptions!$D$8)+F37 -> 620.89061 | G39: =F39*(1-Assumptions!$D$8)+G37 -> 723.63718 | H39: =G39*(1-Assumptions!$D$8)+H37 -> 820.21895 | I39: =H39*(1-Assumptions!$D$8)+I37 -> 911.00581 | J39: =I39*(1-Assumptions!$D$8)+J37 -> 996.34546 | ... M39: =L39*(1-Assumptions!$D$8)+M37 -> 1222.8526 | N39: =M39 -> 1222.8526
A40: Gross MRR ($) | B40: =B39*Assumptions!$D$9 -> 1260 | C40: =C39*Assumptions!$D$9 -> 2444.4 | D40: =D39*Assumptions!$D$9 -> 3557.736 | E40: =E39*Assumptions!$D$9 -> 4604.2718 | F40: =F39*Assumptions!$D$9 -> 5588.0155 | G40: =G39*Assumptions!$D$9 -> 6512.7346 | H40: =H39*Assumptions!$D$9 -> 7381.9705 | I40: =I39*Assumptions!$D$9 -> 8199.0523 | ... M40: =M39*Assumptions!$D$9 -> 11005.673 | N40: =M40 -> 11005.673
A41: Net revenue ($) | B41: =B39*Assumptions!$D$9*(1-Assumptions!$D$10) -> 982.8 | C41: =C39*Assumptions!$D$9*(1-Assumptions!$D$10) -> 1906.632 | D41: =D39*Assumptions!$D$9*(1-Assumptions!$D$10) -> 2775.0341 | E41: =E39*Assumptions!$D$9*(1-Assumptions!$D$10) -> 3591.332 | F41: =F39*Assumptions!$D$9*(1-Assumptions!$D$10) -> 4358.6521 | G41: =G39*Assumptions!$D$9*(1-Assumptions!$D$10) -> 5079.933 | H41: =H39*Assumptions!$D$9*(1-Assumptions!$D$10) -> 5757.937 | I41: =I39*Assumptions!$D$9*(1-Assumptions!$D$10) -> 6395.2608 | ... M41: =M39*Assumptions!$D$9*(1-Assumptions!$D$10) -> 8584.4252 | N41: =SUM(B41:M41) -> 62070.671
A42: Variable cost ($) | B42: =B39*Assumptions!$D$11 -> 168 | C42: =C39*Assumptions!$D$11 -> 325.92 | D42: =D39*Assumptions!$D$11 -> 474.3648 | E42: =E39*Assumptions!$D$11 -> 613.90291 | F42: =F39*Assumptions!$D$11 -> 745.06874 | G42: =G39*Assumptions!$D$11 -> 868.36461 | H42: =H39*Assumptions!$D$11 -> 984.26274 | I42: =I39*Assumptions!$D$11 -> 1093.207 | ... M42: =M39*Assumptions!$D$11 -> 1467.4231 | N42: =SUM(B42:M42) -> 10610.371
A43: Marketing / CAC spend ($) | B43: =B37*Assumptions!$D$12 -> 560 | C43: =C37*Assumptions!$D$12 -> 560 | D43: =D37*Assumptions!$D$12 -> 560 | E43: =E37*Assumptions!$D$12 -> 560 | F43: =F37*Assumptions!$D$12 -> 560 | G43: =G37*Assumptions!$D$12 -> 560 | H43: =H37*Assumptions!$D$12 -> 560 | I43: =I37*Assumptions!$D$12 -> 560 | ... M43: =M37*Assumptions!$D$12 -> 560 | N43: =SUM(B43:M43) -> 6720
A44: Fixed cost ($) | B44: =Assumptions!$D$13 -> 300 | C44: =Assumptions!$D$13 -> 300 | D44: =Assumptions!$D$13 -> 300 | E44: =Assumptions!$D$13 -> 300 | F44: =Assumptions!$D$13 -> 300 | G44: =Assumptions!$D$13 -> 300 | H44: =Assumptions!$D$13 -> 300 | I44: =Assumptions!$D$13 -> 300 | ... M44: =Assumptions!$D$13 -> 300 | N44: =SUM(B44:M44) -> 3600
A45: Net profit / (loss) ($) | B45: =B41-B42-B43-B44 -> -45.2 | C45: =C41-C42-C43-C44 -> 720.712 | D45: =D41-D42-D43-D44 -> 1440.6693 | E45: =E41-E42-E43-E44 -> 2117.4291 | F45: =F41-F42-F43-F44 -> 2753.5834 | G45: =G41-G42-G43-G44 -> 3351.5684 | H45: =H41-H42-H43-H44 -> 3913.6743 | I45: =I41-I42-I43-I44 -> 4442.0538 | ... M45: =M41-M42-M43-M44 -> 6257.0021 | N45: =SUM(B45:M45) -> 41140.3
...

Sheet Scenario Summary
A1: Scenario Summary - Year 1 outcomes
A2: Pulled from the 12-Month Projection sheet.
A4: Metric | B4: Conservative | C4: Base | D4: Optimistic
A5: Active paying users (end of M12) | B5: ='12-Month Projection'!M9 -> 39.216442 | C5: ='12-Month Projection'!M24 -> 240.8976 | D5: ='12-Month Projection'!M39 -> 1222.8526
A6: Gross MRR at M12 ($) | B6: ='12-Month Projection'!M10 -> 313.73154 | C6: ='12-Month Projection'!M25 -> 2047.6296 | D6: ='12-Month Projection'!M40 -> 11005.673
A7: Net revenue at M12 ($) | B7: ='12-Month Projection'!M11 -> 219.61208 | C7: ='12-Month Projection'!M26 -> 1433.3407 | D7: ='12-Month Projection'!M41 -> 8584.4252
A8: Year-1 net revenue ($) | B8: ='12-Month Projection'!N11 -> 1749.5114 | C8: ='12-Month Projection'!N26 -> 10893.999 | D8: ='12-Month Projection'!N41 -> 62070.671
A9: Year-1 marketing spend ($) | B9: ='12-Month Projection'!N13 -> 1080 | C9: ='12-Month Projection'!N28 -> 3072 | D9: ='12-Month Projection'!N43 -> 6720
A10: Year-1 net profit / (loss) ($) | B10: ='12-Month Projection'!N15 -> -3399.1077 | C10: ='12-Month Projection'!N30 -> 1475.6128 | D10: ='12-Month Projection'!N45 -> 41140.3
A11: Cumulative profit at M12 ($) | B11: ='12-Month Projection'!M16 -> -3399.1077 | C11: ='12-Month Projection'!M31 -> 1475.6128 | D11: ='12-Month Projection'!M46 -> 41140.3
A13: Unit economics (from Assumptions)
A14: Metric | B14: Conservative | C14: Base | D14: Optimistic
A15: LTV ($) | B15: =Assumptions!B20 -> 34.166667 | C15: =Assumptions!C20 -> 49.444444 | D15: =Assumptions!D20 -> 97
A16: LTV / CAC ratio | B16: =Assumptions!B21 -> 2.2777778 | C16: =Assumptions!C21 -> 6.1805556 | D16: =Assumptions!D21 -> 24.25
A17: CAC payback (months) | B17: =Assumptions!B22 -> 3.6585366 | C17: =Assumptions!C22 -> 1.7977528 | D17: =Assumptions!D22 -> 0.68728522

Sheet Benchmarks (public)
A1: Public benchmarks gathered in research
A2: Mix of disclosed figures and approximate/estimated values. See 'type' column.
A4: Service / source | B4: Metric | C4: Value | D4: Type | E4: Notes
A5: Balabol (@startup_custdev/75) | B5: CAC | C5: ~2,500 RUB (~$28) | D5: disclosed | E5: English bot; shut down
A6: Balabol | B6: LTV | C6: ~1,200 RUB (~$13) | D6: disclosed | E6: LTV < CAC -> unprofitable
A7: Balabol | B7: Paying subscribers | C7: 6 | D7: disclosed | E7: From 400 total users (~1.5%)
A8: Balabol | B8: Longest subscription | C8: 8 months | D8: disclosed
A9: Bino.School (@binoschool_bot) | B9: New users / month | C9: ~2,000 | D9: disclosed (founder) | E9: Hebrew/Chinese/Spanish/Georgian
A10: Bino.School | B10: Paying users (cohort) | C10: ~300 | D10: disclosed (founder) | E10: ~15% conversion of that cohort
A11: Bino.School | B11: Revenue (2021) | C11: ~$106,600 | D11: approximate | E11: From startup.network profile
A12: AI English bot (captain.works case) | B12: Revenue in 2.5 months | C12: $1,200+ | D12: case study | E12: Solo AI practice bot ramp
A13: TG language tutor (Indie Hackers) | B13: Monthly revenue | C13: ~$3,000 | D13: case study | E13: Selling guides + video lessons
A14: Speak (global, AI conversation) | B14: Annualized revenue (late 2025) | C14: $100M+ | D14: press | E14: OpenAI-backed
A15: Speak | B15: Valuation (Dec 2024) | C15: $1.0B | D15: press | E15: $78M Series C; $162M raised total
A16: Speak | B16: Pricing | C16: $20/mo or $99/yr | D16: disclosed | E16: Bot is funnel into core product
A17: Duolingo (benchmark) | B17: FY2025 revenue | C17: $1.04B (+39% YoY) | D17: SEC filing | E17: Market leader
A18: Duolingo | B18: Paid subscribers (Q4 2025) | C18: 12.2M | D18: SEC filing | E18: ~9% paid conversion
A19: Duolingo | B19: DAU / MAU | C19: 52.7M / 133M | D19: SEC filing
